Workbook

Sheet Lisez-moi
B3: CATALOGUE TCE — PRIX FOURNISSEURS RÉELS
B4: ANELEC Groupe / Blueseatra · version du 09/09/2026 · document interne
B6: 547 | C6: 526 | D6: 289 | E6: 21
B7: articles au catalogue | C7: prix réels relevés | D7: articles comparés sur 2 enseignes ou plus | E7: lignes à compléter
B9: Comment lire ce catalogue | C9: Une feuille par corps d'état. Chaque ligne porte un produit réellement vendu par l'un de vos huit fournisseurs, avec sa marque, ses références, son prix d'achat HT horodaté et le lien vers la fiche. Les colonnes « Conditionnement » et « Point de contrôle » signalent ce qui reste à arbitrer.
B10: Prix retenu | C10: La colonne « Prix achat HT » contient toujours le meilleur prix disponible : votre tarif négocié quand vos comptes le donnent, sinon le prix public relevé. La colonne « Type de prix » précise lequel, et « Remise » chiffre l'écart quand les deux sont connus.
B11: Vos comptes pro | C11: Huit fournisseurs interrogés le même jour. Vos tarifs de compte : Point.P (fichier tarif de l'agence Aubervilliers, 58 250 références), YESSS Électrique (export de 14 rubriques), Rexel (n° 6564380), La Plateforme du Bâtiment (dépôt Aubervilliers), Prolians (Paris Aubervilliers) et SFIC (Pantin). Prix publics : Au Forum du Bâtiment, Chausson Matériaux et Icilux. Ces prix sont vos conditions commerciales : ils restent internes et ne figurent jamais sur un PDF client.
B12: Contrôles avant devis | C12: La feuille « Contrôles qualité » liste chaque ligne qui demande un arbitrage : unité fournisseur différente de votre unité de métré, prix donné pour un conditionnement complet, ou correspondance article/produit encore imparfaite. À traiter avant toute reprise en devis client.
B13: Aucun prix estimé | C13: Aucun prix moyen, indicatif ou reconstitué n'existe dans ce fichier. Une ligne sans prix vérifié reste vide et part en feuille « 99 · À compléter ».
B14: Marges et prix de vente | C14: Les colonnes Marge % et Prix vente HT sont volontairement vides. Saisissez une marge et le prix de vente se calcule automatiquement sur la ligne.
B15: TVA | C15: 20 % par défaut sur les fournitures. Les taux 10 % et 5,5 % s'appliquent à la prestation posée selon la nature des travaux et l'ancienneté du bâtiment, attestation client à l'appui.
B16: Gel des prix | C16: Les prix sont horodatés. Dès qu'un devis est validé, son prix doit être figé (pricing_snapshot) : une évolution ultérieure du catalogue ne modifie jamais un devis déjà validé.
B18: CODE COULEUR
B19: Votre tarif de compte | C19: Prix négocié issu de vos comptes Point.P, YESSS, Rexel, La Plateforme, Prolians ou SFIC.
B20: À vérifier / à valider | C20: Prix réel relevé, mais la correspondance avec votre libellé interne est partielle : ouvrir la fiche avant de l'utiliser en devis.
B21: À compléter | C21: Aucun produit correspondant trouvé chez vos huit fournisseurs.
B22: Prix public | C22: Relevé chez Au Forum du Bâtiment, Chausson Matériaux ou Icilux.

Sheet Recherche
A1: RECHERCHE D'UN ARTICLE
A2: Tapez un mot en B4 (ex. « disjoncteur », « BA13 », « mitigeur ») : toutes les offres correspondantes s'affichent, tous fournisseurs confondus. Pour un même article, l'offre la moins chère apparaît en premier.
A4: Je cherche : | B4: disjoncteur | E4: La recherche porte sur l'article ET sur la désignation du fournisseur.
A6: Article | B6: Fournisseur | C6: Prix HT | D6: Type de prix | E6: Désignation fournisseur | F6: Réf. | G6: Unité de vente | H6: Retrait / disponibilité | I6: Fiabilité | J6: Lot
A7: =IFERROR(IF(INDEX('Base articles'!$D$2:$D$1153,MATCH(1,'Base articles'!$T$2:$T$1153,0))="","",INDEX('Base articles'!$D$2:$D$1153,MATCH(1,'Base articles'!$T$2:$T$1153,0))),"") -> Disjoncteur ph+N 10 A courbe C | B7: =IFERROR(IF(INDEX('Base articles'!$F$2:$F$1153,MATCH(1,'Base articles'!$T$2:$T$1153,0))="","",INDEX('Base articles'!$F$2:$F$1153,MATCH(1,'Base articles'!$T$2:$T$1153,0))),"") -> Au Forum du Bâtiment | C7: =IFERROR(INDEX('Base articles'!$H$2:$H$1153,MATCH(1,'Base articles'!$T$2:$T$1153,0)),"") -> 8.46 | D7: =IFERROR(IF(INDEX('Base articles'!$G$2:$G$1153,MATCH(1,'Base articles'!$T$2:$T$1153,0))="","",INDEX('Base articles'!$G$2:$G$1153,MATCH(1,'Base articles'!$T$2:$T$1153,0))),"") -> Prix public HT | E7: =IFERROR(IF(INDEX('Base articles'!$K$2:$K$1153,MATCH(1,'Base articles'!$T$2:$T$1153,0))="","",INDEX('Base articles'!$K$2:$K$1153,MATCH(1,'Base articles'!$T$2:$T$1153,0))),"") -> Disjoncteur FIXMATIC AUTO 10 A courbe C Phase + Neutre GEWISS GW90606F | F7: =IFERROR(IF(INDEX('Base articles'!$M$2:$M$1153,MATCH(1,'Base articles'!$T$2:$T$1153,0))="","",INDEX('Base articles'!$M$2:$M$1153,MATCH(1,'Base articles'!$T$2:$T$1153,0))),"") -> 753206 | G7: =IFERROR(IF(INDEX('Base articles'!$N$2:$N$1153,MATCH(1,'Base articles'!$T$2:$T$1153,0))="","",INDEX('Base articles'!$N$2:$N$1153,MATCH(1,'Base articles'!$T$2:$T$1153,0))),"") -> u | H7: =IFERROR(IF(INDEX('Base articles'!$P$2:$P$1153,MATCH(1,'Base articles'!$T$2:$T$1153,0))="","",INDEX('Base articles'!$P$2:$P$1153,MATCH(1,'Base articles'!$T$2:$T$1153,0))),"") -> Retrait agence · Livraison selon agence | I7: =IFERROR(IF(INDEX('Base articles'!$Q$2:$Q$1153,MATCH(1,'Base articles'!$T$2:$T$1153,0))="","",INDEX('Base articles'!$Q$2:$Q$1153,MATCH(1,'Base articles'!$T$2:$T$1153,0))),"") -> Élevée | J7: =IFERROR(IF(INDEX('Base articles'!$B$2:$B$1153,MATCH(1,'Base articles'!$T$2:$T$1153,0))="","",INDEX('Base articles'!$B$2:$B$1153,MATCH(1,'Base articles'!$T$2:$T$1153,0))),"") -> 01 · Électricité CFO
A8: =IFERROR(IF(INDEX('Base articles'!$D$2:$D$1153,MATCH(2,'Base articles'!$T$2:$T$1153,0))="","",INDEX('Base articles'!$D$2:$D$1153,MATCH(2,'Base articles'!$T$2:$T$1153,0))),"") -> Disjoncteur ph+N 10 A courbe C | B8: =IFERROR(IF(INDEX('Base articles'!$F$2:$F$1153,MATCH(2,'Base articles'!$T$2:$T$1153,0))="","",INDEX('Base articles'!$F$2:$F$1153,MATCH(2,'Base articles'!$T$2:$T$1153,0))),"") -> Rexel | C8: =IFERROR(INDEX('Base articles'!$H$2:$H$1153,MATCH(2,'Base articles'!$T$2:$T$1153,0)),"") -> 8.78 | D8: =IFERROR(IF(INDEX('Base articles'!$G$2:$G$1153,MATCH(2,'Base articles'!$T$2:$T$1153,0))="","",INDEX('Base articles'!$G$2:$G$1153,MATCH(2,'Base articles'!$T$2:$T$1153,0))),"") -> Votre tarif client | E8: =IFERROR(IF(INDEX('Base articles'!$K$2:$K$1153,MATCH(2,'Base articles'!$T$2:$T$1153,0))="","",INDEX('Base articles'!$K$2:$K$1153,MATCH(2,'Base articles'!$T$2:$T$1153,0))),"") -> HAGER Disjoncteur Phase + Neutre 10A 3kA Courbe C bornes à vis 1 Module | F8: =IFERROR(IF(INDEX('Base articles'!$M$2:$M$1153,MATCH(2,'Base articles'!$T$2:$T$1153,0))="","",INDEX('Base articles'!$M$2:$M$1153,MATCH(2,'Base articles'!$T$2:$T$1153,0))),"") -> HAGMFN710 | G8: =IFERROR(IF(INDEX('Base articles'!$N$2:$N$1153,MATCH(2,'Base articles'!$T$2:$T$1153,0))="","",INDEX('Base articles'!$N$2:$N$1153,MATCH(2,'Base articles'!$T$2:$T$1153,0))),"") | H8: =IFERROR(IF(INDEX('Base articles'!$P$2:$P$1153,MATCH(2,'Base articles'!$T$2:$T$1153,0))="","",INDEX('Base articles'!$P$2:$P$1153,MATCH(2,'Base articles'!$T$2:$T$1153,0))),"") -> Retrait agence · Livraison selon agence | I8: =IFERROR(IF(INDEX('Base articles'!$Q$2:$Q$1153,MATCH(2,'Base articles'!$T$2:$T$1153,0))="","",INDEX('Base articles'!$Q$2:$Q$1153,MATCH(2,'Base articles'!$T$2:$T$1153,0))),"") -> Votre tarif — Rexel | J8: =IFERROR(IF(INDEX('Base articles'!$B$2:$B$1153,MATCH(2,'Base articles'!$T$2:$T$1153,0))="","",INDEX('Base articles'!$B$2:$B$1153,MATCH(2,'Base articles'!$T$2:$T$1153,0))),"") -> 01 · Électricité CFO
A9: =IFERROR(IF(INDEX('Base articles'!$D$2:$D$1153,MATCH(3,'Base articles'!$T$2:$T$1153,0))="","",INDEX('Base articles'!$D$2:$D$1153,MATCH(3,'Base articles'!$T$2:$T$1153,0))),"") -> Disjoncteur ph+N 16 A courbe C | B9: =IFERROR(IF(INDEX('Base articles'!$F$2:$F$1153,MATCH(3,'Base articles'!$T$2:$T$1153,0))="","",INDEX('Base articles'!$F$2:$F$1153,MATCH(3,'Base articles'!$T$2:$T$1153,0))),"") -> Rexel | C9: =IFERROR(INDEX('Base articles'!$H$2:$H$1153,MATCH(3,'Base articles'!$T$2:$T$1153,0)),"") -> 6.89 | D9: =IFERROR(IF(INDEX('Base articles'!$G$2:$G$1153,MATCH(3,'Base articles'!$T$2:$T$1153,0))="","",INDEX('Base articles'!$G$2:$G$1153,MATCH(3,'Base articles'!$T$2:$T$1153,0))),"") -> Votre tarif client | E9: =IFERROR(IF(INDEX('Base articles'!$K$2:$K$1153,MATCH(3,'Base articles'!$T$2:$T$1153,0))="","",INDEX('Base articles'!$K$2:$K$1153,MATCH(3,'Base articles'!$T$2:$T$1153,0))),"") -> ABB SN201L Disjoncteur modulaire - 1P+N - 16A - courbe C - 4500A/6kA - peignable | F9: =IFERROR(IF(INDEX('Base articles'!$M$2:$M$1153,MATCH(3,'Base articles'!$T$2:$T$1153,0))="","",INDEX('Base articles'!$M$2:$M$1153,MATCH(3,'Base articles'!$T$2:$T$1153,0))),"") -> ABB470238 | G9: =IFERROR(IF(INDEX('Base articles'!$N$2:$N$1153,MATCH(3,'Base articles'!$T$2:$T$1153,0))="","",INDEX('Base articles'!$N$2:$N$1153,MATCH(3,'Base articles'!$T$2:$T$1153,0))),"") -> u | H9: =IFERROR(IF(INDEX('Base articles'!$P$2:$P$1153,MATCH(3,'Base articles'!$T$2:$T$1153,0))="","",INDEX('Base articles'!$P$2:$P$1153,MATCH(3,'Base articles'!$T$2:$T$1153,0))),"") -> Retrait agence · Livraison selon agence | I9: =IFERROR(IF(INDEX('Base articles'!$Q$2:$Q$1153,MATCH(3,'Base articles'!$T$2:$T$1153,0))="","",INDEX('Base articles'!$Q$2:$Q$1153,MATCH(3,'Base articles'!$T$2:$T$1153,0))),"") -> Votre tarif — Rexel | J9: =IFERROR(IF(INDEX('Base articles'!$B$2:$B$1153,MATCH(3,'Base articles'!$T$2:$T$1153,0))="","",INDEX('Base articles'!$B$2:$B$1153,MATCH(3,'Base articles'!$T$2:$T$1153,0))),"") -> 01 · Électricité CFO
A10: =IFERROR(IF(INDEX('Base articles'!$D$2:$D$1153,MATCH(4,'Base articles'!$T$2:$T$1153,0))="","",INDEX('Base articles'!$D$2:$D$1153,MATCH(4,'Base articles'!$T$2:$T$1153,0))),"") -> Disjoncteur ph+N 16 A courbe C | B10: =IFERROR(IF(INDEX('Base articles'!$F$2:$F$1153,MATCH(4,'Base articles'!$T$2:$T$1153,0))="","",INDEX('Base articles'!$F$2:$F$1153,MATCH(4,'Base articles'!$T$2:$T$1153,0))),"") -> Au Forum du Bâtiment | C10: =IFERROR(INDEX('Base articles'!$H$2:$H$1153,MATCH(4,'Base articles'!$T$2:$T$1153,0)),"") -> 8.09 | D10: =IFERROR(IF(INDEX('Base articles'!$G$2:$G$1153,MATCH(4,'Base articles'!$T$2:$T$1153,0))="","",INDEX('Base articles'!$G$2:$G$1153,MATCH(4,'Base articles'!$T$2:$T$1153,0))),"") -> Prix public HT | E10: =IFERROR(IF(INDEX('Base articles'!$K$2:$K$1153,MATCH(4,'Base articles'!$T$2:$T$1153,0))="","",INDEX('Base articles'!$K$2:$K$1153,MATCH(4,'Base articles'!$T$2:$T$1153,0))),"") -> Disjoncteur 16 A courbe C Phase + neutre GEWISS GW90607 | F10: =IFERROR(IF(INDEX('Base articles'!$M$2:$M$1153,MATCH(4,'Base articles'!$T$2:$T$1153,0))="","",INDEX('Base articles'!$M$2:$M$1153,MATCH(4,'Base articles'!$T$2:$T$1153,0))),"") -> 753207 | G10: =IFERROR(IF(INDEX('Base articles'!$N$2:$N$1153,MATCH(4,'Base articles'!$T$2:$T$1153,0))="","",INDEX('Base articles'!$N$2:$N$1153,MATCH(4,'Base articles'!$T$2:$T$1153,0))),"") -> u | H10: =IFERROR(IF(INDEX('Base articles'!$P$2:$P$1153,MATCH(4,'Base articles'!$T$2:$T$1153,0))="","",INDEX('Base articles'!$P$2:$P$1153,MATCH(4,'Base articles'!$T$2:$T$1153,0))),"") -> Retrait agence · Livraison selon agence | I10: =IFERROR(IF(INDEX('Base articles'!$Q$2:$Q$1153,MATCH(4,'Base articles'!$T$2:$T$1153,0))="","",INDEX('Base articles'!$Q$2:$Q$1153,MATCH(4,'Base articles'!$T$2:$T$1153,0))),"") -> Élevée | J10: =IFERROR(IF(INDEX('Base articles'!$B$2:$B$1153,MATCH(4,'Base articles'!$T$2:$T$1153,0))="","",INDEX('Base articles'!$B$2:$B$1153,MATCH(4,'Base articles'!$T$2:$T$1153,0))),"") -> 01 · Électricité CFO
A11: =IFERROR(IF(INDEX('Base articles'!$D$2:$D$1153,MATCH(5,'Base articles'!$T$2:$T$1153,0))="","",INDEX('Base articles'!$D$2:$D$1153,MATCH(5,'Base articles'!$T$2:$T$1153,0))),"") -> Disjoncteur ph+N 20 A courbe C | B11: =IFERROR(IF(INDEX('Base articles'!$F$2:$F$1153,MATCH(5,'Base articles'!$T$2:$T$1153,0))="","",INDEX('Base articles'!$F$2:$F$1153,MATCH(5,'Base articles'!$T$2:$T$1153,0))),"") -> Au Forum du Bâtiment | C11: =IFERROR(INDEX('Base articles'!$H$2:$H$1153,MATCH(5,'Base articles'!$T$2:$T$1153,0)),"") -> 5.9 | D11: =IFERROR(IF(INDEX('Base articles'!$G$2:$G$1153,MATCH(5,'Base articles'!$T$2:$T$1153,0))="","",INDEX('Base articles'!$G$2:$G$1153,MATCH(5,'Base articles'!$T$2:$T$1153,0))),"") -> Prix public HT | E11: =IFERROR(IF(INDEX('Base articles'!$K$2:$K$1153,MATCH(5,'Base articles'!$T$2:$T$1153,0))="","",INDEX('Base articles'!$K$2:$K$1153,MATCH(5,'Base articles'!$T$2:$T$1153,0))),"") -> Disjoncteur 20 A courbe C Phase + neutre GEWISS GW90608 | F11: =IFERROR(IF(INDEX('Base articles'!$M$2:$M$1153,MATCH(5,'Base articles'!$T$2:$T$1153,0))="","",INDEX('Base articles'!$M$2:$M$1153,MATCH(5,'Base articles'!$T$2:$T$1153,0))),"") -> 753209 | G11: =IFERROR(IF(INDEX('Base articles'!$N$2:$N$1153,MATCH(5,'Base articles'!$T$2:$T$1153,0))="","",INDEX('Base articles'!$N$2:$N$1153,MATCH(5,'Base articles'!$T$2:$T$1153,0))),"") -> u | H11: =IFERROR(IF(INDEX('Base articles'!$P$2:$P$1153,MATCH(5,'Base articles'!$T$2:$T$1153,0))="","",INDEX('Base articles'!$P$2:$P$1153,MATCH(5,'Base articles'!$T$2:$T$1153,0))),"") -> Retrait agence · Livraison selon agence | I11: =IFERROR(IF(INDEX('Base articles'!$Q$2:$Q$1153,MATCH(5,'Base articles'!$T$2:$T$1153,0))="","",INDEX('Base articles'!$Q$2:$Q$1153,MATCH(5,'Base articles'!$T$2:$T$1153,0))),"") -> Élevée | J11: =IFERROR(IF(INDEX('Base articles'!$B$2:$B$1153,MATCH(5,'Base articles'!$T$2:$T$1153,0))="","",INDEX('Base articles'!$B$2:$B$1153,MATCH(5,'Base articles'!$T$2:$T$1153,0))),"") -> 01 · Électricité CFO
A12: =IFERROR(IF(INDEX('Base articles'!$D$2:$D$1153,MATCH(6,'Base articles'!$T$2:$T$1153,0))="","",INDEX('Base articles'!$D$2:$D$1153,MATCH(6,'Base articles'!$T$2:$T$1153,0))),"") -> Disjoncteur ph+N 20 A courbe C | B12: =IFERROR(IF(INDEX('Base articles'!$F$2:$F$1153,MATCH(6,'Base articles'!$T$2:$T$1153,0))="","",INDEX('Base articles'!$F$2:$F$1153,MATCH(6,'Base articles'!$T$2:$T$1153,0))),"") -> Rexel | C12: =IFERROR(INDEX('Base articles'!$H$2:$H$1153,MATCH(6,'Base articles'!$T$2:$T$1153,0)),"") -> 6.82 | D12: =IFERROR(IF(INDEX('Base articles'!$G$2:$G$1153,MATCH(6,'Base articles'!$T$2:$T$1153,0))="","",INDEX('Base articles'!$G$2:$G$1153,MATCH(6,'Base articles'!$T$2:$T$1153,0))),"") -> Votre tarif client | E12: =IFERROR(IF(INDEX('Base articles'!$K$2:$K$1153,MATCH(6,'Base articles'!$T$2:$T$1153,0))="","",INDEX('Base articles'!$K$2:$K$1153,MATCH(6,'Base articles'!$T$2:$T$1153,0))),"") -> ABB SN201SL Disjoncteur modulaire - 1P+N - 20A - courbe C- 4500A/6kA-peignable-Auto | F12: =IFERROR(IF(INDEX('Base articles'!$M$2:$M$1153,MATCH(6,'Base articles'!$T$2:$T$1153,0))="","",INDEX('Base articles'!$M$2:$M$1153,MATCH(6,'Base articles'!$T$2:$T$1153,0))),"") -> ABB470439 | G12: =IFERROR(IF(INDEX('Base articles'!$N$2:$N$1153,MATCH(6,'Base articles'!$T$2:$T$1153,0))="","",INDEX('Base articles'!$N$2:$N$1153,MATCH(6,'Base articles'!$T$2:$T$1153,0))),"") | H12: =IFERROR(IF(INDEX('Base articles'!$P$2:$P$1153,MATCH(6,'Base articles'!$T$2:$T$1153,0))="","",INDEX('Base articles'!$P$2:$P$1153,MATCH(6,'Base articles'!$T$2:$T$1153,0))),"") -> Retrait agence · Livraison selon agence | I12: =IFERROR(IF(INDEX('Base articles'!$Q$2:$Q$1153,MATCH(6,'Base articles'!$T$2:$T$1153,0))="","",INDEX('Base articles'!$Q$2:$Q$1153,MATCH(6,'Base articles'!$T$2:$T$1153,0))),"") -> Votre tarif — Rexel | J12: =IFERROR(IF(INDEX('Base articles'!$B$2:$B$1153,MATCH(6,'Base articles'!$T$2:$T$1153,0))="","",INDEX('Base articles'!$B$2:$B$1153,MATCH(6,'Base articles'!$T$2:$T$1153,0))),"") -> 01 · Électricité CFO
A13: =IFERROR(IF(INDEX('Base articles'!$D$2:$D$1153,MATCH(7,'Base articles'!$T$2:$T$1153,0))="","",INDEX('Base articles'!$D$2:$D$1153,MATCH(7,'Base articles'!$T$2:$T$1153,0))),"") -> Disjoncteur ph+N 32 A courbe C | B13: =IFERROR(IF(INDEX('Base articles'!$F$2:$F$1153,MATCH(7,'Base articles'!$T$2:$T$1153,0))="","",INDEX('Base articles'!$F$2:$F$1153,MATCH(7,'Base articles'!$T$2:$T$1153,0))),"") -> Au Forum du Bâtiment | C13: =IFERROR(INDEX('Base articles'!$H$2:$H$1153,MATCH(7,'Base articles'!$T$2:$T$1153,0)),"") -> 10.61 | D13: =IFERROR(IF(INDEX('Base articles'!$G$2:$G$1153,MATCH(7,'Base articles'!$T$2:$T$1153,0))="","",INDEX('Base articles'!$G$2:$G$1153,MATCH(7,'Base articles'!$T$2:$T$1153,0))),"") -> Prix public HT | E13: =IFERROR(IF(INDEX('Base articles'!$K$2:$K$1153,MATCH(7,'Base articles'!$T$2:$T$1153,0))="","",INDEX('Base articles'!$K$2:$K$1153,MATCH(7,'Base articles'!$T$2:$T$1153,0))),"") -> Disjoncteur 32 A courbe C Phase + neutre GEWISS GW90610 | F13: =IFERROR(IF(INDEX('Base articles'!$M$2:$M$1153,MATCH(7,'Base articles'!$T$2:$T$1153,0))="","",INDEX('Base articles'!$M$2:$M$1153,MATCH(7,'Base articles'!$T$2:$T$1153,0))),"") -> 753211 | G13: =IFERROR(IF(INDEX('Base articles'!$N$2:$N$1153,MATCH(7,'Base articles'!$T$2:$T$1153,0))="","",INDEX('Base articles'!$N$2:$N$1153,MATCH(7,'Base articles'!$T$2:$T$1153,0))),"") -> u | H13: =IFERROR(IF(INDEX('Base articles'!$P$2:$P$1153,MATCH(7,'Base articles'!$T$2:$T$1153,0))="","",INDEX('Base articles'!$P$2:$P$1153,MATCH(7,'Base articles'!$T$2:$T$1153,0))),"") -> Retrait agence · Livraison selon agence | I13: =IFERROR(IF(INDEX('Base articles'!$Q$2:$Q$1153,MATCH(7,'Base articles'!$T$2:$T$1153,0))="","",INDEX('Base articles'!$Q$2:$Q$1153,MATCH(7,'Base articles'!$T$2:$T$1153,0))),"") -> Élevée | J13: =IFERROR(IF(INDEX('Base articles'!$B$2:$B$1153,MATCH(7,'Base articles'!$T$2:$T$1153,0))="","",INDEX('Base articles'!$B$2:$B$1153,MATCH(7,'Base articles'!$T$2:$T$1153,0))),"") -> 01 · Électricité CFO
A14: =IFERROR(IF(INDEX('Base articles'!$D$2:$D$1153,MATCH(8,'Base articles'!$T$2:$T$1153,0))="","",INDEX('Base articles'!$D$2:$D$1153,MATCH(8,'Base articles'!$T$2:$T$1153,0))),"") -> Disjoncteur ph+N 32 A courbe C | B14: =IFERROR(IF(INDEX('Base articles'!$F$2:$F$1153,MATCH(8,'Base articles'!$T$2:$T$1153,0))="","",INDEX('Base articles'!$F$2:$F$1153,MATCH(8,'Base articles'!$T$2:$T$1153,0))),"") -> Rexel | C14: =IFERROR(INDEX('Base articles'!$H$2:$H$1153,MATCH(8,'Base articles'!$T$2:$T$1153,0)),"") -> 13.1 | D14: =IFERROR(IF(INDEX('Base articles'!$G$2:$G$1153,MATCH(8,'Base articles'!$T$2:$T$1153,0))="","",INDEX('Base articles'!$G$2:$G$1153,MATCH(8,'Base articles'!$T$2:$T$1153,0))),"") -> Votre tarif client | E14: =IFERROR(IF(INDEX('Base articles'!$K$2:$K$1153,MATCH(8,'Base articles'!$T$2:$T$1153,0))="","",INDEX('Base articles'!$K$2:$K$1153,MATCH(8,'Base articles'!$T$2:$T$1153,0))),"") -> HAGER Disjoncteur Phase + Neutre 32A 3kA Courbe C bornes à vis 1 Module | F14: =IFERROR(IF(INDEX('Base articles'!$M$2:$M$1153,MATCH(8,'Base articles'!$T$2:$T$1153,0))="","",INDEX('Base articles'!$M$2:$M$1153,MATCH(8,'Base articles'!$T$2:$T$1153,0))),"") -> HAGMFN732 | G14: =IFERROR(IF(INDEX('Base articles'!$N$2:$N$1153,MATCH(8,'Base articles'!$T$2:$T$1153,0))="","",INDEX('Base articles'!$N$2:$N$1153,MATCH(8,'Base articles'!$T$2:$T$1153,0))),"") | H14: =IFERROR(IF(INDEX('Base articles'!$P$2:$P$1153,MATCH(8,'Base articles'!$T$2:$T$1153,0))="","",INDEX('Base articles'!$P$2:$P$1153,MATCH(8,'Base articles'!$T$2:$T$1153,0))),"") -> Retrait agence · Livraison selon agence | I14: =IFERROR(IF(INDEX('Base articles'!$Q$2:$Q$1153,MATCH(8,'Base articles'!$T$2:$T$1153,0))="","",INDEX('Base articles'!$Q$2:$Q$1153,MATCH(8,'Base articles'!$T$2:$T$1153,0))),"") -> Votre tarif — Rexel | J14: =IFERROR(IF(INDEX('Base articles'!$B$2:$B$1153,MATCH(8,'Base articles'!$T$2:$T$1153,0))="","",INDEX('Base articles'!$B$2:$B$1153,MATCH(8,'Base articles'!$T$2:$T$1153,0))),"") -> 01 · Électricité CFO
A15: =IFERROR(IF(INDEX('Base articles'!$D$2:$D$1153,MATCH(9,'Base articles'!$T$2:$T$1153,0))="","",INDEX('Base articles'!$D$2:$D$1153,MATCH(9,'Base articles'!$T$2:$T$1153,0))),"") -> Disjoncteur tetrapolaire 4P 32 A courbe C | B15: =IFERROR(IF(INDEX('Base articles'!$F$2:$F$1153,MATCH(9,'Base articles'!$T$2:$T$1153,0))="","",INDEX('Base articles'!$F$2:$F$1153,MATCH(9,'Base articles'!$T$2:$T$1153,0))),"") -> Au Forum du Bâtiment | C15: =IFERROR(INDEX('Base articles'!$H$2:$H$1153,MATCH(9,'Base articles'!$T$2:$T$1153,0)),"") -> 107.92 | D15: =IFERROR(IF(INDEX('Base articles'!$G$2:$G$1153,MATCH(9,'Base articles'!$T$2:$T$1153,0))="","",INDEX('Base articles'!$G$2:$G$1153,MATCH(9,'Base articles'!$T$2:$T$1153,0))),"") -> Prix public HT | E15: =IFERROR(IF(INDEX('Base articles'!$K$2:$K$1153,MATCH(9,'Base articles'!$T$2:$T$1153,0))="","",INDEX('Base articles'!$K$2:$K$1153,MATCH(9,'Base articles'!$T$2:$T$1153,0))),"") -> Disjoncteur ACTI9 IC60N 4P courbe C 32 A SCHNEIDER ELECTRIC A9F77432 | F15: =IFERROR(IF(INDEX('Base articles'!$M$2:$M$1153,MATCH(9,'Base articles'!$T$2:$T$1153,0))="","",INDEX('Base articles'!$M$2:$M$1153,MATCH(9,'Base articles'!$T$2:$T$1153,0))),"") -> 610554 | G15: =IFERROR(IF(INDEX('Base articles'!$N$2:$N$1153,MATCH(9,'Base articles'!$T$2:$T$1153,0))="","",INDEX('Base articles'!$N$2:$N$1153,MATCH(9,'Base articles'!$T$2:$T$1153,0))),"") -> u | H15: =IFERROR(IF(INDEX('Base articles'!$P$2:$P$1153,MATCH(9,'Base articles'!$T$2:$T$1153,0))="","",INDEX('Base articles'!$P$2:$P$1153,MATCH(9,'Base articles'!$T$2:$T$1153,0))),"") -> Retrait agence · Livraison selon agence | I15: =IFERROR(IF(INDEX('Base articles'!$Q$2:$Q$1153,MATCH(9,'Base articles'!$T$2:$T$1153,0))="","",INDEX('Base articles'!$Q$2:$Q$1153,MATCH(9,'Base articles'!$T$2:$T$1153,0))),"") -> À vérifier | J15: =IFERROR(IF(INDEX('Base articles'!$B$2:$B$1153,MATCH(9,'Base articles'!$T$2:$T$1153,0))="","",INDEX('Base articles'!$B$2:$B$1153,MATCH(9,'Base articles'!$T$2:$T$1153,0))),"") -> 01 · Électricité CFO
A16: =IFERROR(IF(INDEX('Base articles'!$D$2:$D$1153,MATCH(10,'Base articles'!$T$2:$T$1153,0))="","",INDEX('Base articles'!$D$2:$D$1153,MATCH(10,'Base articles'!$T$2:$T$1153,0))),"") -> Disjoncteur differentiel 20 A 30 mA | B16: =IFERROR(IF(INDEX('Base articles'!$F$2:$F$1153,MATCH(10,'Base articles'!$T$2:$T$1153,0))="","",INDEX('Base articles'!$F$2:$F$1153,MATCH(10,'Base articles'!$T$2:$T$1153,0))),"") -> Rexel | C16: =IFERROR(INDEX('Base articles'!$H$2:$H$1153,MATCH(10,'Base articles'!$T$2:$T$1153,0)),"") -> 135.9 | D16: =IFERROR(IF(INDEX('Base articles'!$G$2:$G$1153,MATCH(10,'Base articles'!$T$2:$T$1153,0))="","",INDEX('Base articles'!$G$2:$G$1153,MATCH(10,'Base articles'!$T$2:$T$1153,0))),"") -> Votre tarif client | E16: =IFERROR(IF(INDEX('Base articles'!$K$2:$K$1153,MATCH(10,'Base articles'!$T$2:$T$1153,0))="","",INDEX('Base articles'!$K$2:$K$1153,MATCH(10,'Base articles'!$T$2:$T$1153,0))),"") -> LEGRAND Disjoncteur diff DX³ 4500 - vis/vis -U+N 230V~ 20A - typeAC -30mA -courbe C - 2M | F16: =IFERROR(IF(INDEX('Base articles'!$M$2:$M$1153,MATCH(10,'Base articles'!$T$2:$T$1153,0))="","",INDEX('Base articles'!$M$2:$M$1153,MATCH(10,'Base articles'!$T$2:$T$1153,0))),"") -> LEG410706 | G16: =IFERROR(IF(INDEX('Base articles'!$N$2:$N$1153,MATCH(10,'Base articles'!$T$2:$T$1153,0))="","",INDEX('Base articles'!$N$2:$N$1153,MATCH(10,'Base articles'!$T$2:$T$1153,0))),"") -> u | H16: =IFERROR(IF(INDEX('Base articles'!$P$2:$P$1153,MATCH(10,'Base articles'!$T$2:$T$1153,0))="","",INDEX('Base articles'!$P$2:$P$1153,MATCH(10,'Base articles'!$T$2:$T$1153,0))),"") -> Retrait agence · Livraison selon agence | I16: =IFERROR(IF(INDEX('Base articles'!$Q$2:$Q$1153,MATCH(10,'Base articles'!$T$2:$T$1153,0))="","",INDEX('Base articles'!$Q$2:$Q$1153,MATCH(10,'Base articles'!$T$2:$T$1153,0))),"") -> Votre tarif — Rexel | J16: =IFERROR(IF(INDEX('Base articles'!$B$2:$B$1153,MATCH(10,'Base articles'!$T$2:$T$1153,0))="","",INDEX('Base articles'!$B$2:$B$1153,MATCH(10,'Base articles'!$T$2:$T$1153,0))),"") -> 01 · Électricité CFO
A17: =IFERROR(IF(INDEX('Base articles'!$D$2:$D$1153,MATCH(11,'Base articles'!$T$2:$T$1153,0))="","",INDEX('Base articles'!$D$2:$D$1153,MATCH(11,'Base articles'!$T$2:$T$1153,0))),"") -> Disjoncteur differentiel 20 A 30 mA | B17: =IFERROR(IF(INDEX('Base articles'!$F$2:$F$1153,MATCH(11,'Base articles'!$T$2:$T$1153,0))="","",INDEX('Base articles'!$F$2:$F$1153,MATCH(11,'Base articles'!$T$2:$T$1153,0))),"") -> Au Forum du Bâtiment | C17: =IFERROR(INDEX('Base articles'!$H$2:$H$1153,MATCH(11,'Base articles'!$T$2:$T$1153,0)),"") -> 140.64 | D17: =IFERROR(IF(INDEX('Base articles'!$G$2:$G$1153,MATCH(11,'Base articles'!$T$2:$T$1153,0))="","",INDEX('Base articles'!$G$2:$G$1153,MATCH(11,'Base articles'!$T$2:$T$1153,0))),"") -> Prix public HT | E17: =IFERROR(IF(INDEX('Base articles'!$K$2:$K$1153,MATCH(11,'Base articles'!$T$2:$T$1153,0))="","",INDEX('Base articles'!$K$2:$K$1153,MATCH(11,'Base articles'!$T$2:$T$1153,0))),"") -> Disjoncteur différentiel RESI9 1P+N 30mA courbe C type Fsi 20A - SCHNEIDER ELECTRIC - R9PDCF20 | F17: =IFERROR(IF(INDEX('Base articles'!$M$2:$M$1153,MATCH(11,'Base articles'!$T$2:$T$1153,0))="","",INDEX('Base articles'!$M$2:$M$1153,MATCH(11,'Base articles'!$T$2:$T$1153,0))),"") -> 750704 | G17: =IFERROR(IF(INDEX('Base articles'!$N$2:$N$1153,MATCH(11,'Base articles'!$T$2:$T$1153,0))="","",INDEX('Base articles'!$N$2:$N$1153,MATCH(11,'Base articles'!$T$2:$T$1153,0))),"") -> u | H17: =IFERROR(IF(INDEX('Base articles'!$P$2:$P$1153,MATCH(11,'Base articles'!$T$2:$T$1153,0))="","",INDEX('Base articles'!$P$2:$P$1153,MATCH(11,'Base articles'!$T$2:$T$1153,0))),"") -> Retrait agence · Livraison selon agence | I17: =IFERROR(IF(INDEX('Base articles'!$Q$2:$Q$1153,MATCH(11,'Base articles'!$T$2:$T$1153,0))="","",INDEX('Base articles'!$Q$2:$Q$1153,MATCH(11,'Base articles'!$T$2:$T$1153,0))),"") -> Élevée | J17: =IFERROR(IF(INDEX('Base articles'!$B$2:$B$1153,MATCH(11,'Base articles'!$T$2:$T$1153,0))="","",INDEX('Base articles'!$B$2:$B$1153,MATCH(11,'Base articles'!$T$2:$T$1153,0))),"") -> 01 · Électricité CFO
A18: =IFERROR(IF(INDEX('Base articles'!$D$2:$D$1153,MATCH(12,'Base articles'!$T$2:$T$1153,0))="","",INDEX('Base articles'!$D$2:$D$1153,MATCH(12,'Base articles'!$T$2:$T$1153,0))),"") -> Disjoncteur differentiel 20 A 30 mA | B18: =IFERROR(IF(INDEX('Base articles'!$F$2:$F$1153,MATCH(12,'Base articles'!$T$2:$T$1153,0))="","",INDEX('Base articles'!$F$2:$F$1153,MATCH(12,'Base articles'!$T$2:$T$1153,0))),"") -> YESSS Électrique | C18: =IFERROR(INDEX('Base articles'!$H$2:$H$1153,MATCH(12,'Base articles'!$T$2:$T$1153,0)),"") -> 251.34 | D18: =IFERROR(IF(INDEX('Base articles'!$G$2:$G$1153,MATCH(12,'Base articles'!$T$2:$T$1153,0))="","",INDEX('Base articles'!$G$2:$G$1153,MATCH(12,'Base articles'!$T$2:$T$1153,0))),"") -> Votre tarif net | E18: =IFERROR(IF(INDEX('Base articles'!$K$2:$K$1153,MATCH(12,'Base articles'!$T$2:$T$1153,0))="","",INDEX('Base articles'!$K$2:$K$1153,MATCH(12,'Base articles'!$T$2:$T$1153,0))),"") -> Disjoncteur différentiel Uni+Neutre 230V~ 16A 30mA Mosaic 2 modules - blanc | F18: =IFERROR(IF(INDEX('Base articles'!$M$2:$M$1153,MATCH(12,'Base articles'!$T$2:$T$1153,0))="","",INDEX('Base articles'!$M$2:$M$1153,MATCH(12,'Base articles'!$T$2:$T$1153,0))),"") -> 077532 | G18: =IFERROR(IF(INDEX('Base articles'!$N$2:$N$1153,MATCH(12,'Base articles'!$T$2:$T$1153,0))="","",INDEX('Base articles'!$N$2:$N$1153,MATCH(12,'Base articles'!$T$2:$T$1153,0))),"") -> u | H18: =IFERROR(IF(INDEX('Base articles'!$P$2:$P$1153,MATCH(12,'Base articles'!$T$2:$T$1153,0))="","",INDEX('Base articles'!$P$2:$P$1153,MATCH(12,'Base articles'!$T$2:$T$1153,0))),"") -> Retrait agence Aubervilliers · Livraison selon agence | I18: =IFERROR(IF(INDEX('Base articles'!$Q$2:$Q$1153,MATCH(12,'Base articles'!$T$2:$T$1153,0))="","",INDEX('Base articles'!$Q$2:$Q$1153,MATCH(12,'Base articles'!$T$2:$T$1153,0))),"") -> Votre tarif — YESSS Électrique | J18: =IFERROR(IF(INDEX('Base articles'!$B$2:$B$1153,MATCH(12,'Base articles'!$T$2:$T$1153,0))="","",INDEX('Base articles'!$B$2:$B$1153,MATCH(12,'Base articles'!$T$2:$T$1153,0))),"") -> 01 · Électricité CFO
A19: =IFERROR(IF(INDEX('Base articles'!$D$2:$D$1153,MATCH(13,'Base articles'!$T$2:$T$1153,0))="","",INDEX('Base articles'!$D$2:$D$1153,MATCH(13,'Base articles'!$T$2:$T$1153,0))),"") -> Borne de connexion automatique 3 entrees | B19: =IFERROR(IF(INDEX('Base articles'!$F$2:$F$1153,MATCH(13,'Base articles'!$T$2:$T$1153,0))="","",INDEX('Base articles'!$F$2:$F$1153,MATCH(13,'Base articles'!$T$2:$T$1153,0))),"") -> YESSS Électrique | C19: =IFERROR(INDEX('Base articles'!$H$2:$H$1153,MATCH(13,'Base articles'!$T$2:$T$1153,0)),"") -> 48.01 | D19: =IFERROR(IF(INDEX('Base articles'!$G$2:$G$1153,MATCH(13,'Base articles'!$T$2:$T$1153,0))="","",INDEX('Base articles'!$G$2:$G$1153,MATCH(13,'Base articles'!$T$2:$T$1153,0))),"") -> Votre tarif net | E19: =IFERROR(IF(INDEX('Base articles'!$K$2:$K$1153,MATCH(13,'Base articles'!$T$2:$T$1153,0))="","",INDEX('Base articles'!$K$2:$K$1153,MATCH(13,'Base articles'!$T$2:$T$1153,0))),"") -> Borne de raccordement pour disjoncteur DX³ 3P+N à connexion automatique - section 6mm² à 25mm² - IP2X | F19: =IFERROR(IF(INDEX('Base articles'!$M$2:$M$1153,MATCH(13,'Base articles'!$T$2:$T$1153,0))="","",INDEX('Base articles'!$M$2:$M$1153,MATCH(13,'Base articles'!$T$2:$T$1153,0))),"") -> 405206 | G19: =IFERROR(IF(INDEX('Base articles'!$N$2:$N$1153,MATCH(13,'Base articles'!$T$2:$T$1153,0))="","",INDEX('Base articles'!$N$2:$N$1153,MATCH(13,'Base articles'!$T$2:$T$1153,0))),"") -> u | H19: =IFERROR(IF(INDEX('Base articles'!$P$2:$P$1153,MATCH(13,'Base articles'!$T$2:$T$1153,0))="","",INDEX('Base articles'!$P$2:$P$1153,MATCH(13,'Base articles'!$T$2:$T$1153,0))),"") -> Retrait agence Aubervilliers · Livraison selon agence | I19: =IFERROR(IF(INDEX('Base articles'!$Q$2:$Q$1153,MATCH(13,'Base articles'!$T$2:$T$1153,0))="","",INDEX('Base articles'!$Q$2:$Q$1153,MATCH(13,'Base articles'!$T$2:$T$1153,0))),"") -> Votre tarif — YESSS Électrique | J19: =IFERROR(IF(INDEX('Base articles'!$B$2:$B$1153,MATCH(13,'Base articles'!$T$2:$T$1153,0))="","",INDEX('Base articles'!$B$2:$B$1153,MATCH(13,'Base articles'!$T$2:$T$1153,0))),"") -> 01 · Électricité CFO
A20: =IFERROR(IF(INDEX('Base articles'!$D$2:$D$1153,MATCH(14,'Base articles'!$T$2:$T$1153,0))="","",INDEX('Base articles'!$D$2:$D$1153,MATCH(14,'Base articles'!$T$2:$T$1153,0))),"") | B20: =IFERROR(IF(INDEX('Base articles'!$F$2:$F$1153,MATCH(14,'Base articles'!$T$2:$T$1153,0))="","",INDEX('Base articles'!$F$2:$F$1153,MATCH(14,'Base articles'!$T$2:$T$1153,0))),"") | C20: =IFERROR(INDEX('Base articles'!$H$2:$H$1153,MATCH(14,'Base articles'!$T$2:$T$1153,0)),"") | D20: =IFERROR(IF(INDEX('Base articles'!$G$2:$G$1153,MATCH(14,'Base articles'!$T$2:$T$1153,0))="","",INDEX('Base articles'!$G$2:$G$1153,MATCH(14,'Base articles'!$T$2:$T$1153,0))),"") | E20: =IFERROR(IF(INDEX('Base articles'!$K$2:$K$1153,MATCH(14,'Base articles'!$T$2:$T$1153,0))="","",INDEX('Base articles'!$K$2:$K$1153,MATCH(14,'Base articles'!$T$2:$T$1153,0))),"") | F20: =IFERROR(IF(INDEX('Base articles'!$M$2:$M$1153,MATCH(14,'Base articles'!$T$2:$T$1153,0))="","",INDEX('Base articles'!$M$2:$M$1153,MATCH(14,'Base articles'!$T$2:$T$1153,0))),"") | G20: =IFERROR(IF(INDEX('Base articles'!$N$2:$N$1153,MATCH(14,'Base articles'!$T$2:$T$1153,0))="","",INDEX('Base articles'!$N$2:$N$1153,MATCH(14,'Base articles'!$T$2:$T$1153,0))),"") | H20: =IFERROR(IF(INDEX('Base articles'!$P$2:$P$1153,MATCH(14,'Base articles'!$T$2:$T$1153,0))="","",INDEX('Base articles'!$P$2:$P$1153,MATCH(14,'Base articles'!$T$2:$T$1153,0))),"") | I20: =IFERROR(IF(INDEX('Base articles'!$Q$2:$Q$1153,MATCH(14,'Base articles'!$T$2:$T$1153,0))="","",INDEX('Base articles'!$Q$2:$Q$1153,MATCH(14,'Base articles'!$T$2:$T$1153,0))),"") | J20: =IFERROR(IF(INDEX('Base articles'!$B$2:$B$1153,MATCH(14,'Base articles'!$T$2:$T$1153,0))="","",INDEX('Base articles'!$B$2:$B$1153,MATCH(14,'Base articles'!$T$2:$T$1153,0))),"")
A21: =IFERROR(IF(INDEX('Base articles'!$D$2:$D$1153,MATCH(15,'Base articles'!$T$2:$T$1153,0))="","",INDEX('Base articles'!$D$2:$D$1153,MATCH(15,'Base articles'!$T$2:$T$1153,0))),"") | B21: =IFERROR(IF(INDEX('Base articles'!$F$2:$F$1153,MATCH(15,'Base articles'!$T$2:$T$1153,0))="","",INDEX('Base articles'!$F$2:$F$1153,MATCH(15,'Base articles'!$T$2:$T$1153,0))),"") | C21: =IFERROR(INDEX('Base articles'!$H$2:$H$1153,MATCH(15,'Base articles'!$T$2:$T$1153,0)),"") | D21: =IFERROR(IF(INDEX('Base articles'!$G$2:$G$1153,MATCH(15,'Base articles'!$T$2:$T$1153,0))="","",INDEX('Base articles'!$G$2:$G$1153,MATCH(15,'Base articles'!$T$2:$T$1153,0))),"") | E21: =IFERROR(IF(INDEX('Base articles'!$K$2:$K$1153,MATCH(15,'Base articles'!$T$2:$T$1153,0))="","",INDEX('Base articles'!$K$2:$K$1153,MATCH(15,'Base articles'!$T$2:$T$1153,0))),"") | F21: =IFERROR(IF(INDEX('Base articles'!$M$2:$M$1153,MATCH(15,'Base articles'!$T$2:$T$1153,0))="","",INDEX('Base articles'!$M$2:$M$1153,MATCH(15,'Base articles'!$T$2:$T$1153,0))),"") | G21: =IFERROR(IF(INDEX('Base articles'!$N$2:$N$1153,MATCH(15,'Base articles'!$T$2:$T$1153,0))="","",INDEX('Base articles'!$N$2:$N$1153,MATCH(15,'Base articles'!$T$2:$T$1153,0))),"") | H21: =IFERROR(IF(INDEX('Base articles'!$P$2:$P$1153,MATCH(15,'Base articles'!$T$2:$T$1153,0))="","",INDEX('Base articles'!$P$2:$P$1153,MATCH(15,'Base articles'!$T$2:$T$1153,0))),"") | I21: =IFERROR(IF(INDEX('Base articles'!$Q$2:$Q$1153,MATCH(15,'Base articles'!$T$2:$T$1153,0))="","",INDEX('Base articles'!$Q$2:$Q$1153,MATCH(15,'Base articles'!$T$2:$T$1153,0))),"") | J21: =IFERROR(IF(INDEX('Base articles'!$B$2:$B$1153,MATCH(15,'Base articles'!$T$2:$T$1153,0))="","",INDEX('Base articles'!$B$2:$B$1153,MATCH(15,'Base articles'!$T$2:$T$1153,0))),"")
A22: =IFERROR(IF(INDEX('Base articles'!$D$2:$D$1153,MATCH(16,'Base articles'!$T$2:$T$1153,0))="","",INDEX('Base articles'!$D$2:$D$1153,MATCH(16,'Base articles'!$T$2:$T$1153,0))),"") | B22: =IFERROR(IF(INDEX('Base articles'!$F$2:$F$1153,MATCH(16,'Base articles'!$T$2:$T$1153,0))="","",INDEX('Base articles'!$F$2:$F$1153,MATCH(16,'Base articles'!$T$2:$T$1153,0))),"") | C22: =IFERROR(INDEX('Base articles'!$H$2:$H$1153,MATCH(16,'Base articles'!$T$2:$T$1153,0)),"") | D22: =IFERROR(IF(INDEX('Base articles'!$G$2:$G$1153,MATCH(16,'Base articles'!$T$2:$T$1153,0))="","",INDEX('Base articles'!$G$2:$G$1153,MATCH(16,'Base articles'!$T$2:$T$1153,0))),"") | E22: =IFERROR(IF(INDEX('Base articles'!$K$2:$K$1153,MATCH(16,'Base articles'!$T$2:$T$1153,0))="","",INDEX('Base articles'!$K$2:$K$1153,MATCH(16,'Base articles'!$T$2:$T$1153,0))),"") | F22: =IFERROR(IF(INDEX('Base articles'!$M$2:$M$1153,MATCH(16,'Base articles'!$T$2:$T$1153,0))="","",INDEX('Base articles'!$M$2:$M$1153,MATCH(16,'Base articles'!$T$2:$T$1153,0))),"") | G22: =IFERROR(IF(INDEX('Base articles'!$N$2:$N$1153,MATCH(16,'Base articles'!$T$2:$T$1153,0))="","",INDEX('Base articles'!$N$2:$N$1153,MATCH(16,'Base articles'!$T$2:$T$1153,0))),"") | H22: =IFERROR(IF(INDEX('Base articles'!$P$2:$P$1153,MATCH(16,'Base articles'!$T$2:$T$1153,0))="","",INDEX('Base articles'!$P$2:$P$1153,MATCH(16,'Base articles'!$T$2:$T$1153,0))),"") | I22: =IFERROR(IF(INDEX('Base articles'!$Q$2:$Q$1153,MATCH(16,'Base articles'!$T$2:$T$1153,0))="","",INDEX('Base articles'!$Q$2:$Q$1153,MATCH(16,'Base articles'!$T$2:$T$1153,0))),"") | J22: =IFERROR(IF(INDEX('Base articles'!$B$2:$B$1153,MATCH(16,'Base articles'!$T$2:$T$1153,0))="","",INDEX('Base articles'!$B$2:$B$1153,MATCH(16,'Base articles'!$T$2:$T$1153,0))),"")
A23: =IFERROR(IF(INDEX('Base articles'!$D$2:$D$1153,MATCH(17,'Base articles'!$T$2:$T$1153,0))="","",INDEX('Base articles'!$D$2:$D$1153,MATCH(17,'Base articles'!$T$2:$T$1153,0))),"") | B23: =IFERROR(IF(INDEX('Base articles'!$F$2:$F$1153,MATCH(17,'Base articles'!$T$2:$T$1153,0))="","",INDEX('Base articles'!$F$2:$F$1153,MATCH(17,'Base articles'!$T$2:$T$1153,0))),"") | C23: =IFERROR(INDEX('Base articles'!$H$2:$H$1153,MATCH(17,'Base articles'!$T$2:$T$1153,0)),"") | D23: =IFERROR(IF(INDEX('Base articles'!$G$2:$G$1153,MATCH(17,'Base articles'!$T$2:$T$1153,0))="","",INDEX('Base articles'!$G$2:$G$1153,MATCH(17,'Base articles'!$T$2:$T$1153,0))),"") | E23: =IFERROR(IF(INDEX('Base articles'!$K$2:$K$1153,MATCH(17,'Base articles'!$T$2:$T$1153,0))="","",INDEX('Base articles'!$K$2:$K$1153,MATCH(17,'Base articles'!$T$2:$T$1153,0))),"") | F23: =IFERROR(IF(INDEX('Base articles'!$M$2:$M$1153,MATCH(17,'Base articles'!$T$2:$T$1153,0))="","",INDEX('Base articles'!$M$2:$M$1153,MATCH(17,'Base articles'!$T$2:$T$1153,0))),"") | G23: =IFERROR(IF(INDEX('Base articles'!$N$2:$N$1153,MATCH(17,'Base articles'!$T$2:$T$1153,0))="","",INDEX('Base articles'!$N$2:$N$1153,MATCH(17,'Base articles'!$T$2:$T$1153,0))),"") | H23: =IFERROR(IF(INDEX('Base articles'!$P$2:$P$1153,MATCH(17,'Base articles'!$T$2:$T$1153,0))="","",INDEX('Base articles'!$P$2:$P$1153,MATCH(17,'Base articles'!$T$2:$T$1153,0))),"") | I23: =IFERROR(IF(INDEX('Base articles'!$Q$2:$Q$1153,MATCH(17,'Base articles'!$T$2:$T$1153,0))="","",INDEX('Base articles'!$Q$2:$Q$1153,MATCH(17,'Base articles'!$T$2:$T$1153,0))),"") | J23: =IFERROR(IF(INDEX('Base articles'!$B$2:$B$1153,MATCH(17,'Base articles'!$T$2:$T$1153,0))="","",INDEX('Base articles'!$B$2:$B$1153,MATCH(17,'Base articles'!$T$2:$T$1153,0))),"")
A24: =IFERROR(IF(INDEX('Base articles'!$D$2:$D$1153,MATCH(18,'Base articles'!$T$2:$T$1153,0))="","",INDEX('Base articles'!$D$2:$D$1153,MATCH(18,'Base articles'!$T$2:$T$1153,0))),"") | B24: =IFERROR(IF(INDEX('Base articles'!$F$2:$F$1153,MATCH(18,'Base articles'!$T$2:$T$1153,0))="","",INDEX('Base articles'!$F$2:$F$1153,MATCH(18,'Base articles'!$T$2:$T$1153,0))),"") | C24: =IFERROR(INDEX('Base articles'!$H$2:$H$1153,MATCH(18,'Base articles'!$T$2:$T$1153,0)),"") | D24: =IFERROR(IF(INDEX('Base articles'!$G$2:$G$1153,MATCH(18,'Base articles'!$T$2:$T$1153,0))="","",INDEX('Base articles'!$G$2:$G$1153,MATCH(18,'Base articles'!$T$2:$T$1153,0))),"") | E24: =IFERROR(IF(INDEX('Base articles'!$K$2:$K$1153,MATCH(18,'Base articles'!$T$2:$T$1153,0))="","",INDEX('Base articles'!$K$2:$K$1153,MATCH(18,'Base articles'!$T$2:$T$1153,0))),"") | F24: =IFERROR(IF(INDEX('Base articles'!$M$2:$M$1153,MATCH(18,'Base articles'!$T$2:$T$1153,0))="","",INDEX('Base articles'!$M$2:$M$1153,MATCH(18,'Base articles'!$T$2:$T$1153,0))),"") | G24: =IFERROR(IF(INDEX('Base articles'!$N$2:$N$1153,MATCH(18,'Base articles'!$T$2:$T$1153,0))="","",INDEX('Base articles'!$N$2:$N$1153,MATCH(18,'Base articles'!$T$2:$T$1153,0))),"") | H24: =IFERROR(IF(INDEX('Base articles'!$P$2:$P$1153,MATCH(18,'Base articles'!$T$2:$T$1153,0))="","",INDEX('Base articles'!$P$2:$P$1153,MATCH(18,'Base articles'!$T$2:$T$1153,0))),"") | I24: =IFERROR(IF(INDEX('Base articles'!$Q$2:$Q$1153,MATCH(18,'Base articles'!$T$2:$T$1153,0))="","",INDEX('Base articles'!$Q$2:$Q$1153,MATCH(18,'Base articles'!$T$2:$T$1153,0))),"") | J24: =IFERROR(IF(INDEX('Base articles'!$B$2:$B$1153,MATCH(18,'Base articles'!$T$2:$T$1153,0))="","",INDEX('Base articles'!$B$2:$B$1153,MATCH(18,'Base articles'!$T$2:$T$1153,0))),"")
A25: =IFERROR(IF(INDEX('Base articles'!$D$2:$D$1153,MATCH(19,'Base articles'!$T$2:$T$1153,0))="","",INDEX('Base articles'!$D$2:$D$1153,MATCH(19,'Base articles'!$T$2:$T$1153,0))),"") | B25: =IFERROR(IF(INDEX('Base articles'!$F$2:$F$1153,MATCH(19,'Base articles'!$T$2:$T$1153,0))="","",INDEX('Base articles'!$F$2:$F$1153,MATCH(19,'Base articles'!$T$2:$T$1153,0))),"") | C25: =IFERROR(INDEX('Base articles'!$H$2:$H$1153,MATCH(19,'Base articles'!$T$2:$T$1153,0)),"") | D25: =IFERROR(IF(INDEX('Base articles'!$G$2:$G$1153,MATCH(19,'Base articles'!$T$2:$T$1153,0))="","",INDEX('Base articles'!$G$2:$G$1153,MATCH(19,'Base articles'!$T$2:$T$1153,0))),"") | E25: =IFERROR(IF(INDEX('Base articles'!$K$2:$K$1153,MATCH(19,'Base articles'!$T$2:$T$1153,0))="","",INDEX('Base articles'!$K$2:$K$1153,MATCH(19,'Base articles'!$T$2:$T$1153,0))),"") | F25: =IFERROR(IF(INDEX('Base articles'!$M$2:$M$1153,MATCH(19,'Base articles'!$T$2:$T$1153,0))="","",INDEX('Base articles'!$M$2:$M$1153,MATCH(19,'Base articles'!$T$2:$T$1153,0))),"") | G25: =IFERROR(IF(INDEX('Base articles'!$N$2:$N$1153,MATCH(19,'Base articles'!$T$2:$T$1153,0))="","",INDEX('Base articles'!$N$2:$N$1153,MATCH(19,'Base articles'!$T$2:$T$1153,0))),"") | H25: =IFERROR(IF(INDEX('Base articles'!$P$2:$P$1153,MATCH(19,'Base articles'!$T$2:$T$1153,0))="","",INDEX('Base articles'!$P$2:$P$1153,MATCH(19,'Base articles'!$T$2:$T$1153,0))),"") | I25: =IFERROR(IF(INDEX('Base articles'!$Q$2:$Q$1153,MATCH(19,'Base articles'!$T$2:$T$1153,0))="","",INDEX('Base articles'!$Q$2:$Q$1153,MATCH(19,'Base articles'!$T$2:$T$1153,0))),"") | J25: =IFERROR(IF(INDEX('Base articles'!$B$2:$B$1153,MATCH(19,'Base articles'!$T$2:$T$1153,0))="","",INDEX('Base articles'!$B$2:$B$1153,MATCH(19,'Base articles'!$T$2:$T$1153,0))),"")
A26: =IFERROR(IF(INDEX('Base articles'!$D$2:$D$1153,MATCH(20,'Base articles'!$T$2:$T$1153,0))="","",INDEX('Base articles'!$D$2:$D$1153,MATCH(20,'Base articles'!$T$2:$T$1153,0))),"") | B26: =IFERROR(IF(INDEX('Base articles'!$F$2:$F$1153,MATCH(20,'Base articles'!$T$2:$T$1153,0))="","",INDEX('Base articles'!$F$2:$F$1153,MATCH(20,'Base articles'!$T$2:$T$1153,0))),"") | C26: =IFERROR(INDEX('Base articles'!$H$2:$H$1153,MATCH(20,'Base articles'!$T$2:$T$1153,0)),"") | D26: =IFERROR(IF(INDEX('Base articles'!$G$2:$G$1153,MATCH(20,'Base articles'!$T$2:$T$1153,0))="","",INDEX('Base articles'!$G$2:$G$1153,MATCH(20,'Base articles'!$T$2:$T$1153,0))),"") | E26: =IFERROR(IF(INDEX('Base articles'!$K$2:$K$1153,MATCH(20,'Base articles'!$T$2:$T$1153,0))="","",INDEX('Base articles'!$K$2:$K$1153,MATCH(20,'Base articles'!$T$2:$T$1153,0))),"") | F26: =IFERROR(IF(INDEX('Base articles'!$M$2:$M$1153,MATCH(20,'Base articles'!$T$2:$T$1153,0))="","",INDEX('Base articles'!$M$2:$M$1153,MATCH(20,'Base articles'!$T$2:$T$1153,0))),"") | G26: =IFERROR(IF(INDEX('Base articles'!$N$2:$N$1153,MATCH(20,'Base articles'!$T$2:$T$1153,0))="","",INDEX('Base articles'!$N$2:$N$1153,MATCH(20,'Base articles'!$T$2:$T$1153,0))),"") | H26: =IFERROR(IF(INDEX('Base articles'!$P$2:$P$1153,MATCH(20,'Base articles'!$T$2:$T$1153,0))="","",INDEX('Base articles'!$P$2:$P$1153,MATCH(20,'Base articles'!$T$2:$T$1153,0))),"") | I26: =IFERROR(IF(INDEX('Base articles'!$Q$2:$Q$1153,MATCH(20,'Base articles'!$T$2:$T$1153,0))="","",INDEX('Base articles'!$Q$2:$Q$1153,MATCH(20,'Base articles'!$T$2:$T$1153,0))),"") | J26: =IFERROR(IF(INDEX('Base articles'!$B$2:$B$1153,MATCH(20,'Base articles'!$T$2:$T$1153,0))="","",INDEX('Base articles'!$B$2:$B$1153,MATCH(20,'Base articles'!$T$2:$T$1153,0))),"")
A27: =IFERROR(IF(INDEX('Base articles'!$D$2:$D$1153,MATCH(21,'Base articles'!$T$2:$T$1153,0))="","",INDEX('Base articles'!$D$2:$D$1153,MATCH(21,'Base articles'!$T$2:$T$1153,0))),"") | B27: =IFERROR(IF(INDEX('Base articles'!$F$2:$F$1153,MATCH(21,'Base articles'!$T$2:$T$1153,0))="","",INDEX('Base articles'!$F$2:$F$1153,MATCH(21,'Base articles'!$T$2:$T$1153,0))),"") | C27: =IFERROR(INDEX('Base articles'!$H$2:$H$1153,MATCH(21,'Base articles'!$T$2:$T$1153,0)),"") | D27: =IFERROR(IF(INDEX('Base articles'!$G$2:$G$1153,MATCH(21,'Base articles'!$T$2:$T$1153,0))="","",INDEX('Base articles'!$G$2:$G$1153,MATCH(21,'Base articles'!$T$2:$T$1153,0))),"") | E27: =IFERROR(IF(INDEX('Base articles'!$K$2:$K$1153,MATCH(21,'Base articles'!$T$2:$T$1153,0))="","",INDEX('Base articles'!$K$2:$K$1153,MATCH(21,'Base articles'!$T$2:$T$1153,0))),"") | F27: =IFERROR(IF(INDEX('Base articles'!$M$2:$M$1153,MATCH(21,'Base articles'!$T$2:$T$1153,0))="","",INDEX('Base articles'!$M$2:$M$1153,MATCH(21,'Base articles'!$T$2:$T$1153,0))),"") | G27: =IFERROR(IF(INDEX('Base articles'!$N$2:$N$1153,MATCH(21,'Base articles'!$T$2:$T$1153,0))="","",INDEX('Base articles'!$N$2:$N$1153,MATCH(21,'Base articles'!$T$2:$T$1153,0))),"") | H27: =IFERROR(IF(INDEX('Base articles'!$P$2:$P$1153,MATCH(21,'Base articles'!$T$2:$T$1153,0))="","",INDEX('Base articles'!$P$2:$P$1153,MATCH(21,'Base articles'!$T$2:$T$1153,0))),"") | I27: =IFERROR(IF(INDEX('Base articles'!$Q$2:$Q$1153,MATCH(21,'Base articles'!$T$2:$T$1153,0))="","",INDEX('Base articles'!$Q$2:$Q$1153,MATCH(21,'Base articles'!$T$2:$T$1153,0))),"") | J27: =IFERROR(IF(INDEX('Base articles'!$B$2:$B$1153,MATCH(21,'Base articles'!$T$2:$T$1153,0))="","",INDEX('Base articles'!$B$2:$B$1153,MATCH(21,'Base articles'!$T$2:$T$1153,0))),"")
A28: =IFERROR(IF(INDEX('Base articles'!$D$2:$D$1153,MATCH(22,'Base articles'!$T$2:$T$1153,0))="","",INDEX('Base articles'!$D$2:$D$1153,MATCH(22,'Base articles'!$T$2:$T$1153,0))),"") | B28: =IFERROR(IF(INDEX('Base articles'!$F$2:$F$1153,MATCH(22,'Base articles'!$T$2:$T$1153,0))="","",INDEX('Base articles'!$F$2:$F$1153,MATCH(22,'Base articles'!$T$2:$T$1153,0))),"") | C28: =IFERROR(INDEX('Base articles'!$H$2:$H$1153,MATCH(22,'Base articles'!$T$2:$T$1153,0)),"") | D28: =IFERROR(IF(INDEX('Base articles'!$G$2:$G$1153,MATCH(22,'Base articles'!$T$2:$T$1153,0))="","",INDEX('Base articles'!$G$2:$G$1153,MATCH(22,'Base articles'!$T$2:$T$1153,0))),"") | E28: =IFERROR(IF(INDEX('Base articles'!$K$2:$K$1153,MATCH(22,'Base articles'!$T$2:$T$1153,0))="","",INDEX('Base articles'!$K$2:$K$1153,MATCH(22,'Base articles'!$T$2:$T$1153,0))),"") | F28: =IFERROR(IF(INDEX('Base articles'!$M$2:$M$1153,MATCH(22,'Base articles'!$T$2:$T$1153,0))="","",INDEX('Base articles'!$M$2:$M$1153,MATCH(22,'Base articles'!$T$2:$T$1153,0))),"") | G28: =IFERROR(IF(INDEX('Base articles'!$N$2:$N$1153,MATCH(22,'Base articles'!$T$2:$T$1153,0))="","",INDEX('Base articles'!$N$2:$N$1153,MATCH(22,'Base articles'!$T$2:$T$1153,0))),"") | H28: =IFERROR(IF(INDEX('Base articles'!$P$2:$P$1153,MATCH(22,'Base articles'!$T$2:$T$1153,0))="","",INDEX('Base articles'!$P$2:$P$1153,MATCH(22,'Base articles'!$T$2:$T$1153,0))),"") | I28: =IFERROR(IF(INDEX('Base articles'!$Q$2:$Q$1153,MATCH(22,'Base articles'!$T$2:$T$1153,0))="","",INDEX('Base articles'!$Q$2:$Q$1153,MATCH(22,'Base articles'!$T$2:$T$1153,0))),"") | J28: =IFERROR(IF(INDEX('Base articles'!$B$2:$B$1153,MATCH(22,'Base articles'!$T$2:$T$1153,0))="","",INDEX('Base articles'!$B$2:$B$1153,MATCH(22,'Base articles'!$T$2:$T$1153,0))),"")
A29: =IFERROR(IF(INDEX('Base articles'!$D$2:$D$1153,MATCH(23,'Base articles'!$T$2:$T$1153,0))="","",INDEX('Base articles'!$D$2:$D$1153,MATCH(23,'Base articles'!$T$2:$T$1153,0))),"") | B29: =IFERROR(IF(INDEX('Base articles'!$F$2:$F$1153,MATCH(23,'Base articles'!$T$2:$T$1153,0))="","",INDEX('Base articles'!$F$2:$F$1153,MATCH(23,'Base articles'!$T$2:$T$1153,0))),"") | C29: =IFERROR(INDEX('Base articles'!$H$2:$H$1153,MATCH(23,'Base articles'!$T$2:$T$1153,0)),"") | D29: =IFERROR(IF(INDEX('Base articles'!$G$2:$G$1153,MATCH(23,'Base articles'!$T$2:$T$1153,0))="","",INDEX('Base articles'!$G$2:$G$1153,MATCH(23,'Base articles'!$T$2:$T$1153,0))),"") | E29: =IFERROR(IF(INDEX('Base articles'!$K$2:$K$1153,MATCH(23,'Base articles'!$T$2:$T$1153,0))="","",INDEX('Base articles'!$K$2:$K$1153,MATCH(23,'Base articles'!$T$2:$T$1153,0))),"") | F29: =IFERROR(IF(INDEX('Base articles'!$M$2:$M$1153,MATCH(23,'Base articles'!$T$2:$T$1153,0))="","",INDEX('Base articles'!$M$2:$M$1153,MATCH(23,'Base articles'!$T$2:$T$1153,0))),"") | G29: =IFERROR(IF(INDEX('Base articles'!$N$2:$N$1153,MATCH(23,'Base articles'!$T$2:$T$1153,0))="","",INDEX('Base articles'!$N$2:$N$1153,MATCH(23,'Base articles'!$T$2:$T$1153,0))),"") | H29: =IFERROR(IF(INDEX('Base articles'!$P$2:$P$1153,MATCH(23,'Base articles'!$T$2:$T$1153,0))="","",INDEX('Base articles'!$P$2:$P$1153,MATCH(23,'Base articles'!$T$2:$T$1153,0))),"") | I29: =IFERROR(IF(INDEX('Base articles'!$Q$2:$Q$1153,MATCH(23,'Base articles'!$T$2:$T$1153,0))="","",INDEX('Base articles'!$Q$2:$Q$1153,MATCH(23,'Base articles'!$T$2:$T$1153,0))),"") | J29: =IFERROR(IF(INDEX('Base articles'!$B$2:$B$1153,MATCH(23,'Base articles'!$T$2:$T$1153,0))="","",INDEX('Base articles'!$B$2:$B$1153,MATCH(23,'Base articles'!$T$2:$T$1153,0))),"")
A30: =IFERROR(IF(INDEX('Base articles'!$D$2:$D$1153,MATCH(24,'Base articles'!$T$2:$T$1153,0))="","",INDEX('Base articles'!$D$2:$D$1153,MATCH(24,'Base articles'!$T$2:$T$1153,0))),"") | B30: =IFERROR(IF(INDEX('Base articles'!$F$2:$F$1153,MATCH(24,'Base articles'!$T$2:$T$1153,0))="","",INDEX('Base articles'!$F$2:$F$1153,MATCH(24,'Base articles'!$T$2:$T$1153,0))),"") | C30: =IFERROR(INDEX('Base articles'!$H$2:$H$1153,MATCH(24,'Base articles'!$T$2:$T$1153,0)),"") | D30: =IFERROR(IF(INDEX('Base articles'!$G$2:$G$1153,MATCH(24,'Base articles'!$T$2:$T$1153,0))="","",INDEX('Base articles'!$G$2:$G$1153,MATCH(24,'Base articles'!$T$2:$T$1153,0))),"") | E30: =IFERROR(IF(INDEX('Base articles'!$K$2:$K$1153,MATCH(24,'Base articles'!$T$2:$T$1153,0))="","",INDEX('Base articles'!$K$2:$K$1153,MATCH(24,'Base articles'!$T$2:$T$1153,0))),"") | F30: =IFERROR(IF(INDEX('Base articles'!$M$2:$M$1153,MATCH(24,'Base articles'!$T$2:$T$1153,0))="","",INDEX('Base articles'!$M$2:$M$1153,MATCH(24,'Base articles'!$T$2:$T$1153,0))),"") | G30: =IFERROR(IF(INDEX('Base articles'!$N$2:$N$1153,MATCH(24,'Base articles'!$T$2:$T$1153,0))="","",INDEX('Base articles'!$N$2:$N$1153,MATCH(24,'Base articles'!$T$2:$T$1153,0))),"") | H30: =IFERROR(IF(INDEX('Base articles'!$P$2:$P$1153,MATCH(24,'Base articles'!$T$2:$T$1153,0))="","",INDEX('Base articles'!$P$2:$P$1153,MATCH(24,'Base articles'!$T$2:$T$1153,0))),"") | I30: =IFERROR(IF(INDEX('Base articles'!$Q$2:$Q$1153,MATCH(24,'Base articles'!$T$2:$T$1153,0))="","",INDEX('Base articles'!$Q$2:$Q$1153,MATCH(24,'Base articles'!$T$2:$T$1153,0))),"") | J30: =IFERROR(IF(INDEX('Base articles'!$B$2:$B$1153,MATCH(24,'Base articles'!$T$2:$T$1153,0))="","",INDEX('Base articles'!$B$2:$B$1153,MATCH(24,'Base articles'!$T$2:$T$1153,0))),"")
A31: =IFERROR(IF(INDEX('Base articles'!$D$2:$D$1153,MATCH(25,'Base articles'!$T$2:$T$1153,0))="","",INDEX('Base articles'!$D$2:$D$1153,MATCH(25,'Base articles'!$T$2:$T$1153,0))),"") | B31: =IFERROR(IF(INDEX('Base articles'!$F$2:$F$1153,MATCH(25,'Base articles'!$T$2:$T$1153,0))="","",INDEX('Base articles'!$F$2:$F$1153,MATCH(25,'Base articles'!$T$2:$T$1153,0))),"") | C31: =IFERROR(INDEX('Base articles'!$H$2:$H$1153,MATCH(25,'Base articles'!$T$2:$T$1153,0)),"") | D31: =IFERROR(IF(INDEX('Base articles'!$G$2:$G$1153,MATCH(25,'Base articles'!$T$2:$T$1153,0))="","",INDEX('Base articles'!$G$2:$G$1153,MATCH(25,'Base articles'!$T$2:$T$1153,0))),"") | E31: =IFERROR(IF(INDEX('Base articles'!$K$2:$K$1153,MATCH(25,'Base articles'!$T$2:$T$1153,0))="","",INDEX('Base articles'!$K$2:$K$1153,MATCH(25,'Base articles'!$T$2:$T$1153,0))),"") | F31: =IFERROR(IF(INDEX('Base articles'!$M$2:$M$1153,MATCH(25,'Base articles'!$T$2:$T$1153,0))="","",INDEX('Base articles'!$M$2:$M$1153,MATCH(25,'Base articles'!$T$2:$T$1153,0))),"") | G31: =IFERROR(IF(INDEX('Base articles'!$N$2:$N$1153,MATCH(25,'Base articles'!$T$2:$T$1153,0))="","",INDEX('Base articles'!$N$2:$N$1153,MATCH(25,'Base articles'!$T$2:$T$1153,0))),"") | H31: =IFERROR(IF(INDEX('Base articles'!$P$2:$P$1153,MATCH(25,'Base articles'!$T$2:$T$1153,0))="","",INDEX('Base articles'!$P$2:$P$1153,MATCH(25,'Base articles'!$T$2:$T$1153,0))),"") | I31: =IFERROR(IF(INDEX('Base articles'!$Q$2:$Q$1153,MATCH(25,'Base articles'!$T$2:$T$1153,0))="","",INDEX('Base articles'!$Q$2:$Q$1153,MATCH(25,'Base articles'!$T$2:$T$1153,0))),"") | J31: =IFERROR(IF(INDEX('Base articles'!$B$2:$B$1153,MATCH(25,'Base articles'!$T$2:$T$1153,0))="","",INDEX('Base articles'!$B$2:$B$1153,MATCH(25,'Base articles'!$T$2:$T$1153,0))),"")
A32: =IFERROR(IF(INDEX('Base articles'!$D$2:$D$1153,MATCH(26,'Base articles'!$T$2:$T$1153,0))="","",INDEX('Base articles'!$D$2:$D$1153,MATCH(26,'Base articles'!$T$2:$T$1153,0))),"") | B32: =IFERROR(IF(INDEX('Base articles'!$F$2:$F$1153,MATCH(26,'Base articles'!$T$2:$T$1153,0))="","",INDEX('Base articles'!$F$2:$F$1153,MATCH(26,'Base articles'!$T$2:$T$1153,0))),"") | C32: =IFERROR(INDEX('Base articles'!$H$2:$H$1153,MATCH(26,'Base articles'!$T$2:$T$1153,0)),"") | D32: =IFERROR(IF(INDEX('Base articles'!$G$2:$G$1153,MATCH(26,'Base articles'!$T$2:$T$1153,0))="","",INDEX('Base articles'!$G$2:$G$1153,MATCH(26,'Base articles'!$T$2:$T$1153,0))),"") | E32: =IFERROR(IF(INDEX('Base articles'!$K$2:$K$1153,MATCH(26,'Base articles'!$T$2:$T$1153,0))="","",INDEX('Base articles'!$K$2:$K$1153,MATCH(26,'Base articles'!$T$2:$T$1153,0))),"") | F32: =IFERROR(IF(INDEX('Base articles'!$M$2:$M$1153,MATCH(26,'Base articles'!$T$2:$T$1153,0))="","",INDEX('Base articles'!$M$2:$M$1153,MATCH(26,'Base articles'!$T$2:$T$1153,0))),"") | G32: =IFERROR(IF(INDEX('Base articles'!$N$2:$N$1153,MATCH(26,'Base articles'!$T$2:$T$1153,0))="","",INDEX('Base articles'!$N$2:$N$1153,MATCH(26,'Base articles'!$T$2:$T$1153,0))),"") | H32: =IFERROR(IF(INDEX('Base articles'!$P$2:$P$1153,MATCH(26,'Base articles'!$T$2:$T$1153,0))="","",INDEX('Base articles'!$P$2:$P$1153,MATCH(26,'Base articles'!$T$2:$T$1153,0))),"") | I32: =IFERROR(IF(INDEX('Base articles'!$Q$2:$Q$1153,MATCH(26,'Base articles'!$T$2:$T$1153,0))="","",INDEX('Base articles'!$Q$2:$Q$1153,MATCH(26,'Base articles'!$T$2:$T$1153,0))),"") | J32: =IFERROR(IF(INDEX('Base articles'!$B$2:$B$1153,MATCH(26,'Base articles'!$T$2:$T$1153,0))="","",INDEX('Base articles'!$B$2:$B$1153,MATCH(26,'Base articles'!$T$2:$T$1153,0))),"")
A33: =IFERROR(IF(INDEX('Base articles'!$D$2:$D$1153,MATCH(27,'Base articles'!$T$2:$T$1153,0))="","",INDEX('Base articles'!$D$2:$D$1153,MATCH(27,'Base articles'!$T$2:$T$1153,0))),"") | B33: =IFERROR(IF(INDEX('Base articles'!$F$2:$F$1153,MATCH(27,'Base articles'!$T$2:$T$1153,0))="","",INDEX('Base articles'!$F$2:$F$1153,MATCH(27,'Base articles'!$T$2:$T$1153,0))),"") | C33: =IFERROR(INDEX('Base articles'!$H$2:$H$1153,MATCH(27,'Base articles'!$T$2:$T$1153,0)),"") | D33: =IFERROR(IF(INDEX('Base articles'!$G$2:$G$1153,MATCH(27,'Base articles'!$T$2:$T$1153,0))="","",INDEX('Base articles'!$G$2:$G$1153,MATCH(27,'Base articles'!$T$2:$T$1153,0))),"") | E33: =IFERROR(IF(INDEX('Base articles'!$K$2:$K$1153,MATCH(27,'Base articles'!$T$2:$T$1153,0))="","",INDEX('Base articles'!$K$2:$K$1153,MATCH(27,'Base articles'!$T$2:$T$1153,0))),"") | F33: =IFERROR(IF(INDEX('Base articles'!$M$2:$M$1153,MATCH(27,'Base articles'!$T$2:$T$1153,0))="","",INDEX('Base articles'!$M$2:$M$1153,MATCH(27,'Base articles'!$T$2:$T$1153,0))),"") | G33: =IFERROR(IF(INDEX('Base articles'!$N$2:$N$1153,MATCH(27,'Base articles'!$T$2:$T$1153,0))="","",INDEX('Base articles'!$N$2:$N$1153,MATCH(27,'Base articles'!$T$2:$T$1153,0))),"") | H33: =IFERROR(IF(INDEX('Base articles'!$P$2:$P$1153,MATCH(27,'Base articles'!$T$2:$T$1153,0))="","",INDEX('Base articles'!$P$2:$P$1153,MATCH(27,'Base articles'!$T$2:$T$1153,0))),"") | I33: =IFERROR(IF(INDEX('Base articles'!$Q$2:$Q$1153,MATCH(27,'Base articles'!$T$2:$T$1153,0))="","",INDEX('Base articles'!$Q$2:$Q$1153,MATCH(27,'Base articles'!$T$2:$T$1153,0))),"") | J33: =IFERROR(IF(INDEX('Base articles'!$B$2:$B$1153,MATCH(27,'Base articles'!$T$2:$T$1153,0))="","",INDEX('Base articles'!$B$2:$B$1153,MATCH(27,'Base articles'!$T$2:$T$1153,0))),"")
A34: =IFERROR(IF(INDEX('Base articles'!$D$2:$D$1153,MATCH(28,'Base articles'!$T$2:$T$1153,0))="","",INDEX('Base articles'!$D$2:$D$1153,MATCH(28,'Base articles'!$T$2:$T$1153,0))),"") | B34: =IFERROR(IF(INDEX('Base articles'!$F$2:$F$1153,MATCH(28,'Base articles'!$T$2:$T$1153,0))="","",INDEX('Base articles'!$F$2:$F$1153,MATCH(28,'Base articles'!$T$2:$T$1153,0))),"") | C34: =IFERROR(INDEX('Base articles'!$H$2:$H$1153,MATCH(28,'Base articles'!$T$2:$T$1153,0)),"") | D34: =IFERROR(IF(INDEX('Base articles'!$G$2:$G$1153,MATCH(28,'Base articles'!$T$2:$T$1153,0))="","",INDEX('Base articles'!$G$2:$G$1153,MATCH(28,'Base articles'!$T$2:$T$1153,0))),"") | E34: =IFERROR(IF(INDEX('Base articles'!$K$2:$K$1153,MATCH(28,'Base articles'!$T$2:$T$1153,0))="","",INDEX('Base articles'!$K$2:$K$1153,MATCH(28,'Base articles'!$T$2:$T$1153,0))),"") | F34: =IFERROR(IF(INDEX('Base articles'!$M$2:$M$1153,MATCH(28,'Base articles'!$T$2:$T$1153,0))="","",INDEX('Base articles'!$M$2:$M$1153,MATCH(28,'Base articles'!$T$2:$T$1153,0))),"") | G34: =IFERROR(IF(INDEX('Base articles'!$N$2:$N$1153,MATCH(28,'Base articles'!$T$2:$T$1153,0))="","",INDEX('Base articles'!$N$2:$N$1153,MATCH(28,'Base articles'!$T$2:$T$1153,0))),"") | H34: =IFERROR(IF(INDEX('Base articles'!$P$2:$P$1153,MATCH(28,'Base articles'!$T$2:$T$1153,0))="","",INDEX('Base articles'!$P$2:$P$1153,MATCH(28,'Base articles'!$T$2:$T$1153,0))),"") | I34: =IFERROR(IF(INDEX('Base articles'!$Q$2:$Q$1153,MATCH(28,'Base articles'!$T$2:$T$1153,0))="","",INDEX('Base articles'!$Q$2:$Q$1153,MATCH(28,'Base articles'!$T$2:$T$1153,0))),"") | J34: =IFERROR(IF(INDEX('Base articles'!$B$2:$B$1153,MATCH(28,'Base articles'!$T$2:$T$1153,0))="","",INDEX('Base articles'!$B$2:$B$1153,MATCH(28,'Base articles'!$T$2:$T$1153,0))),"")
A35: =IFERROR(IF(INDEX('Base articles'!$D$2:$D$1153,MATCH(29,'Base articles'!$T$2:$T$1153,0))="","",INDEX('Base articles'!$D$2:$D$1153,MATCH(29,'Base articles'!$T$2:$T$1153,0))),"") | B35: =IFERROR(IF(INDEX('Base articles'!$F$2:$F$1153,MATCH(29,'Base articles'!$T$2:$T$1153,0))="","",INDEX('Base articles'!$F$2:$F$1153,MATCH(29,'Base articles'!$T$2:$T$1153,0))),"") | C35: =IFERROR(INDEX('Base articles'!$H$2:$H$1153,MATCH(29,'Base articles'!$T$2:$T$1153,0)),"") | D35: =IFERROR(IF(INDEX('Base articles'!$G$2:$G$1153,MATCH(29,'Base articles'!$T$2:$T$1153,0))="","",INDEX('Base articles'!$G$2:$G$1153,MATCH(29,'Base articles'!$T$2:$T$1153,0))),"") | E35: =IFERROR(IF(INDEX('Base articles'!$K$2:$K$1153,MATCH(29,'Base articles'!$T$2:$T$1153,0))="","",INDEX('Base articles'!$K$2:$K$1153,MATCH(29,'Base articles'!$T$2:$T$1153,0))),"") | F35: =IFERROR(IF(INDEX('Base articles'!$M$2:$M$1153,MATCH(29,'Base articles'!$T$2:$T$1153,0))="","",INDEX('Base articles'!$M$2:$M$1153,MATCH(29,'Base articles'!$T$2:$T$1153,0))),"") | G35: =IFERROR(IF(INDEX('Base articles'!$N$2:$N$1153,MATCH(29,'Base articles'!$T$2:$T$1153,0))="","",INDEX('Base articles'!$N$2:$N$1153,MATCH(29,'Base articles'!$T$2:$T$1153,0))),"") | H35: =IFERROR(IF(INDEX('Base articles'!$P$2:$P$1153,MATCH(29,'Base articles'!$T$2:$T$1153,0))="","",INDEX('Base articles'!$P$2:$P$1153,MATCH(29,'Base articles'!$T$2:$T$1153,0))),"") | I35: =IFERROR(IF(INDEX('Base articles'!$Q$2:$Q$1153,MATCH(29,'Base articles'!$T$2:$T$1153,0))="","",INDEX('Base articles'!$Q$2:$Q$1153,MATCH(29,'Base articles'!$T$2:$T$1153,0))),"") | J35: =IFERROR(IF(INDEX('Base articles'!$B$2:$B$1153,MATCH(29,'Base articles'!$T$2:$T$1153,0))="","",INDEX('Base articles'!$B$2:$B$1153,MATCH(29,'Base articles'!$T$2:$T$1153,0))),"")
A36: =IFERROR(IF(INDEX('Base articles'!$D$2:$D$1153,MATCH(30,'Base articles'!$T$2:$T$1153,0))="","",INDEX('Base articles'!$D$2:$D$1153,MATCH(30,'Base articles'!$T$2:$T$1153,0))),"") | B36: =IFERROR(IF(INDEX('Base articles'!$F$2:$F$1153,MATCH(30,'Base articles'!$T$2:$T$1153,0))="","",INDEX('Base articles'!$F$2:$F$1153,MATCH(30,'Base articles'!$T$2:$T$1153,0))),"") | C36: =IFERROR(INDEX('Base articles'!$H$2:$H$1153,MATCH(30,'Base articles'!$T$2:$T$1153,0)),"") | D36: =IFERROR(IF(INDEX('Base articles'!$G$2:$G$1153,MATCH(30,'Base articles'!$T$2:$T$1153,0))="","",INDEX('Base articles'!$G$2:$G$1153,MATCH(30,'Base articles'!$T$2:$T$1153,0))),"") | E36: =IFERROR(IF(INDEX('Base articles'!$K$2:$K$1153,MATCH(30,'Base articles'!$T$2:$T$1153,0))="","",INDEX('Base articles'!$K$2:$K$1153,MATCH(30,'Base articles'!$T$2:$T$1153,0))),"") | F36: =IFERROR(IF(INDEX('Base articles'!$M$2:$M$1153,MATCH(30,'Base articles'!$T$2:$T$1153,0))="","",INDEX('Base articles'!$M$2:$M$1153,MATCH(30,'Base articles'!$T$2:$T$1153,0))),"") | G36: =IFERROR(IF(INDEX('Base articles'!$N$2:$N$1153,MATCH(30,'Base articles'!$T$2:$T$1153,0))="","",INDEX('Base articles'!$N$2:$N$1153,MATCH(30,'Base articles'!$T$2:$T$1153,0))),"") | H36: =IFERROR(IF(INDEX('Base articles'!$P$2:$P$1153,MATCH(30,'Base articles'!$T$2:$T$1153,0))="","",INDEX('Base articles'!$P$2:$P$1153,MATCH(30,'Base articles'!$T$2:$T$1153,0))),"") | I36: =IFERROR(IF(INDEX('Base articles'!$Q$2:$Q$1153,MATCH(30,'Base articles'!$T$2:$T$1153,0))="","",INDEX('Base articles'!$Q$2:$Q$1153,MATCH(30,'Base articles'!$T$2:$T$1153,0))),"") | J36: =IFERROR(IF(INDEX('Base articles'!$B$2:$B$1153,MATCH(30,'Base articles'!$T$2:$T$1153,0))="","",INDEX('Base articles'!$B$2:$B$1153,MATCH(30,'Base articles'!$T$2:$T$1153,0))),"")
